<robot
  name="robotican_lizi">
  <link
    name="base_link">
    <inertial>
      <origin
        xyz="0.0041783 0.0052424 0.04047"
        rpy="0 0 0" />
      <mass
        value="0.47025" />
      <inertia
        ixx="0.004176"
        ixy="0.00013487"
        ixz="-0.00050843"
        iyy="0.0083952"
        iyz="8.2807E-06"
        izz="0.0098763" />
    </inertial>
    <visual>
      <origin
        xyz="0 0 0"
        rpy="0 0 0" />
      <geometry>
        <mesh
          filename="package://robotican_lizi/meshes/base_link.STL" />
      </geometry>
      <material
        name="">
        <color
          rgba="0.79216 0.81961 0.93333 1" />
      </material>
    </visual>
    <collision>
      <origin
        xyz="0 0 0"
        rpy="0 0 0" />
      <geometry>
        <mesh
          filename="package://robotican_lizi/meshes/base_link.STL" />
      </geometry>
    </collision>
  </link>
  <link
    name="footprint_link" />
  <joint
    name="footprint_joint"
    type="fixed">
    <origin
      xyz="0 0 -0.0762"
      rpy="0 0 0" />
    <parent
      link="base_link" />
    <child
      link="footprint_link" />
    <axis
      xyz="0 0 0" />
  </joint>
  <link
    name="laser_link">
    <inertial>
      <origin
        xyz="-3.976E-05 0.00016529 -0.022904"
        rpy="0 0 0" />
      <mass
        value="0.13302" />
      <inertia
        ixx="6.9591E-05"
        ixy="-6.1652E-08"
        ixz="-1.627E-07"
        iyy="7.0066E-05"
        iyz="-4.9495E-07"
        izz="4.5841E-05" />
    </inertial>
    <visual>
      <origin
        xyz="0 0 0"
        rpy="0 0 0" />
      <geometry>
        <mesh
          filename="package://robotican_lizi/meshes/laser_link.STL" />
      </geometry>
      <material
        name="">
        <color
          rgba="0.75294 0.75294 0.75294 1" />
      </material>
    </visual>
    <collision>
      <origin
        xyz="0 0 0"
        rpy="0 0 0" />
      <geometry>
        <mesh
          filename="package://robotican_lizi/meshes/laser_link.STL" />
      </geometry>
    </collision>
  </link>
  <joint
    name="laser_joint"
    type="fixed">
    <origin
      xyz="0.1495 0 0.069005"
      rpy="0 0 0" />
    <parent
      link="base_link" />
    <child
      link="laser_link" />
    <axis
      xyz="0 0 0" />
  </joint>
  <link
    name="sr300_link">
    <inertial>
      <origin
        xyz="-0.019521 -4.9406E-07 0.0028518"
        rpy="0 0 0" />
      <mass
        value="0.064787" />
      <inertia
        ixx="5.9362E-05"
        ixy="-6.331E-10"
        ixz="-5.1662E-06"
        iyy="2.5368E-05"
        iyz="4.3621E-11"
        izz="7.6483E-05" />
    </inertial>
    <visual>
      <origin
        xyz="0 0 0"
        rpy="0 0 0" />
      <geometry>
        <mesh
          filename="package://robotican_lizi/meshes/sr300_link.STL" />
      </geometry>
      <material
        name="">
        <color
          rgba="0.29804 0.29804 0.29804 1" />
      </material>
    </visual>
    <collision>
      <origin
        xyz="0 0 0"
        rpy="0 0 0" />
      <geometry>
        <mesh
          filename="package://robotican_lizi/meshes/sr300_link.STL" />
      </geometry>
    </collision>
  </link>
  <joint
    name="sr300_joint"
    type="fixed">
    <origin
      xyz="0.19382 0 0.10646"
      rpy="0 0 0" />
    <parent
      link="base_link" />
    <child
      link="sr300_link" />
    <axis
      xyz="0 0 0" />
  </joint>
  <link
    name="left_urf_link" />
  <joint
    name="left_urf_joint"
    type="fixed">
    <origin
      xyz="0.014542 0.1055 0.0902"
      rpy="0 0 1.5708" />
    <parent
      link="base_link" />
    <child
      link="left_urf_link" />
    <axis
      xyz="0 0 0" />
  </joint>
  <link
    name="rear_urf_link" />
  <joint
    name="rear_urf_joint"
    type="fixed">
    <origin
      xyz="-0.18 0 0.0902"
      rpy="0 0 3.1416" />
    <parent
      link="base_link" />
    <child
      link="rear_urf_link" />
    <axis
      xyz="0 0 0" />
  </joint>
  <link
    name="right_urf_link" />
  <joint
    name="right_urf_joint"
    type="fixed">
    <origin
      xyz="0.014542 -0.1055 0.0902"
      rpy="0 0 -1.5708" />
    <parent
      link="base_link" />
    <child
      link="right_urf_link" />
    <axis
      xyz="0 0 0" />
  </joint>
  <link
    name="FL_wheel_link">
    <inertial>
      <origin
        xyz="-9.1354E-06 -0.001115 4.3697E-07"
        rpy="0 0 0" />
      <mass
        value="0.20156" />
      <inertia
        ixx="0.00032875"
        ixy="8.8617E-09"
        ixz="8.2109E-12"
        iyy="0.00062398"
        iyz="5.8123E-10"
        izz="0.00032873" />
    </inertial>
    <visual>
      <origin
        xyz="0 0 0"
        rpy="0 0 0" />
      <geometry>
        <mesh
          filename="package://robotican_lizi/meshes/FL_wheel_link.STL" />
      </geometry>
      <material
        name="">
        <color
          rgba="0.79216 0.81961 0.93333 1" />
      </material>
    </visual>
    <collision>
      <origin
        xyz="0 0 0"
        rpy="0 0 0" />
      <geometry>
        <mesh
          filename="package://robotican_lizi/meshes/FL_wheel_link.STL" />
      </geometry>
    </collision>
  </link>
  <joint
    name="FL_wheel_joint"
    type="continuous">
    <origin
      xyz="0.13 0.13321 0"
      rpy="0 0 0" />
    <parent
      link="base_link" />
    <child
      link="FL_wheel_link" />
    <axis
      xyz="0 1 0" />
  </joint>
  <link
    name="RL_wheel_link">
    <inertial>
      <origin
        xyz="-9.1354E-06 -0.001115 4.3697E-07"
        rpy="0 0 0" />
      <mass
        value="0.20156" />
      <inertia
        ixx="0.00032875"
        ixy="8.8617E-09"
        ixz="8.2109E-12"
        iyy="0.00062398"
        iyz="5.8123E-10"
        izz="0.00032873" />
    </inertial>
    <visual>
      <origin
        xyz="0 0 0"
        rpy="0 0 0" />
      <geometry>
        <mesh
          filename="package://robotican_lizi/meshes/RL_wheel_link.STL" />
      </geometry>
      <material
        name="">
        <color
          rgba="0.79216 0.81961 0.93333 1" />
      </material>
    </visual>
    <collision>
      <origin
        xyz="0 0 0"
        rpy="0 0 0" />
      <geometry>
        <mesh
          filename="package://robotican_lizi/meshes/RL_wheel_link.STL" />
      </geometry>
    </collision>
  </link>
  <joint
    name="RL_wheel_joint"
    type="continuous">
    <origin
      xyz="-0.13 0.13321 0"
      rpy="0 0 0" />
    <parent
      link="base_link" />
    <child
      link="RL_wheel_link" />
    <axis
      xyz="0 -1 0" />
  </joint>
  <link
    name="FR_wheel_link">
    <inertial>
      <origin
        xyz="9.1354E-06 0.001115 4.3696E-07"
        rpy="0 0 0" />
      <mass
        value="0.20156" />
      <inertia
        ixx="0.00032875"
        ixy="8.8617E-09"
        ixz="-8.2128E-12"
        iyy="0.00062398"
        iyz="-5.8127E-10"
        izz="0.00032873" />
    </inertial>
    <visual>
      <origin
        xyz="0 0 0"
        rpy="0 0 0" />
      <geometry>
        <mesh
          filename="package://robotican_lizi/meshes/FR_wheel_link.STL" />
      </geometry>
      <material
        name="">
        <color
          rgba="0.79216 0.81961 0.93333 1" />
      </material>
    </visual>
    <collision>
      <origin
        xyz="0 0 0"
        rpy="0 0 0" />
      <geometry>
        <mesh
          filename="package://robotican_lizi/meshes/FR_wheel_link.STL" />
      </geometry>
    </collision>
  </link>
  <joint
    name="FR_wheell_joint"
    type="continuous">
    <origin
      xyz="0.13 -0.13321 0"
      rpy="0 0 0" />
    <parent
      link="base_link" />
    <child
      link="FR_wheel_link" />
    <axis
      xyz="0 1 0" />
  </joint>
  <link
    name="RR_wheel_link">
    <inertial>
      <origin
        xyz="-9.1354E-06 0.001115 -4.3696E-07"
        rpy="0 0 0" />
      <mass
        value="0.20156" />
      <inertia
        ixx="0.00032875"
        ixy="-8.8617E-09"
        ixz="-8.2125E-12"
        iyy="0.00062398"
        iyz="5.8127E-10"
        izz="0.00032873" />
    </inertial>
    <visual>
      <origin
        xyz="0 0 0"
        rpy="0 0 0" />
      <geometry>
        <mesh
          filename="package://robotican_lizi/meshes/RR_wheel_link.STL" />
      </geometry>
      <material
        name="">
        <color
          rgba="0.79216 0.81961 0.93333 1" />
      </material>
    </visual>
    <collision>
      <origin
        xyz="0 0 0"
        rpy="0 0 0" />
      <geometry>
        <mesh
          filename="package://robotican_lizi/meshes/RR_wheel_link.STL" />
      </geometry>
    </collision>
  </link>
  <joint
    name="RR_wheel_joint"
    type="continuous">
    <origin
      xyz="-0.13 -0.13321 0"
      rpy="0 0 0" />
    <parent
      link="base_link" />
    <child
      link="RR_wheel_link" />
    <axis
      xyz="0 -1 0" />
  </joint>
  <link
    name="front_camera_link" />
  <joint
    name="front_camera_joint"
    type="fixed">
    <origin
      xyz="0.17275 0.068 0.0202"
      rpy="0 0 0" />
    <parent
      link="base_link" />
    <child
      link="front_camera_link" />
    <axis
      xyz="0 0 0" />
  </joint>
</robot>