<?xml version="1.0" encoding="UTF-8"?>


<robot
  xmlns:xacro="http://www.ros.org/wiki/xacro" name="lizi">
    
  <xacro:property name="M_PI" value="3.14159265358979" />
  
  <link
    name="base_link">
    <inertial>
      <origin
        xyz="0.0030152 0.00524236473615063 0.0404695921883583"
        rpy="0 0 0" />
      <mass
        value="5.470251986966204" />
      <inertia
        ixx="0.00417603662557191"
        ixy="-0.000134866417293007"
        ixz="0.000508431621755966"
        iyy="0.00839520338356809"
        iyz="-8.28069581519405E-06"
        izz="0.00987627573316224" />
    </inertial>
    <visual>
      <origin
        xyz="0 0 0"
        rpy="0 0 0" />
      <geometry>
        <mesh
          filename="package://lizi_description/meshes/base.STL" />
      </geometry>
      <material
        name="">
        <color
          rgba="0.0 0.396 0.0 1" />
      </material>
    </visual>
    <collision>
      <origin
        xyz="0 0 0"
        rpy="0 0 0" />
      <geometry>
        <mesh
          filename="package://lizi_description/meshes/base.STL" />
      </geometry>
    </collision>
  </link>
  <link
    name="base_footprint" />
  <joint
    name="base_footprint_joint"
    type="fixed">
    <origin
      xyz="0 0 0.0762"
      rpy="0 0 0" />
    <parent
      link="base_footprint" />
    <child
      link="base_link" />
    <axis
      xyz="0 0 0" />
  </joint>
  <link
    name="laser_link">
    <inertial>
      <origin
        xyz="-3.97603836856664E-05 0.000165294162433824 -0.0229041562479139"
        rpy="0 0 0" />
      <mass
        value="0.133020399094738" />
      <inertia
        ixx="6.95907638582217E-05"
        ixy="6.16520646181772E-08"
        ixz="1.62702618497649E-07"
        iyy="7.00657431385141E-05"
        iyz="4.949487469302E-07"
        izz="4.58412779272461E-05" />
    </inertial>
    <visual>
      <origin
        xyz="0 0 0"
        rpy="0 0 0" />
      <geometry>
        <mesh
          filename="package://lizi_description/meshes/lidar.STL" />
      </geometry>
      <material
        name="">
        <color
          rgba="0.075 0.075 0.075 1" />
      </material>
    </visual>
    <collision>
      <origin
        xyz="0 0 0"
        rpy="0 0 0" />
      <geometry>
        <mesh
          filename="package://lizi_description/meshes/lidar.STL" />
      </geometry>
    </collision>
  </link>
  <joint
    name="laser_joint"
    type="fixed">
    <origin
      xyz="0.1495 0 0.0790052090034135"
      rpy="0 0 0" />
    <parent
      link="base_link" />
    <child
      link="laser_link" />
    <axis
      xyz="0 0 0" />
  </joint>
  <link
    name="camera_link">
    <inertial>
      <origin
        xyz="-0.0131032740950953 0.000595431416784195 -0.000126402566328898"
        rpy="0 0 0" />
      <mass
        value="0.0446256012085415" />
      <inertia
        ixx="2.62358816469286E-05"
        ixy="3.51148589025837E-07"
        ixz="3.91275344099617E-11"
        iyy="4.02618646244089E-06"
        iyz="-6.05255657176089E-09"
        izz="2.64982132448101E-05" />
    </inertial>
    <visual>
      <origin
        xyz="0 0 0"
        rpy="0 0 0" />
      <geometry>
        <mesh
          filename="package://lizi_description/meshes/depth_cam.STL" />
      </geometry>
      <material
        name="">
        <color
          rgba="0.47 0.47 0.47 1" />
      </material>
    </visual>
    <collision>
      <origin
        xyz="0 0 0"
        rpy="0 0 0" />
      <geometry>
        <mesh
          filename="package://lizi_description/meshes/depth_cam.STL" />
      </geometry>
    </collision>
  </link>
  <joint
    name="depth_cam_joint"
    type="fixed">
    <origin
      xyz="0.176417327435888 0.000478302882383396 0.121932872993568"
      rpy="0 0 0" />
    <parent
      link="base_link" />
    <child
      link="camera_link" />
    <axis
      xyz="0 0 0" />
  </joint>
  <link
    name="left_urf_link" />
  <joint
    name="left_urf_joint"
    type="fixed">
    <origin
      xyz="0.0145422866940573 0.1055 0.0902"
      rpy="0 0 1.5707963267949" />
    <parent
      link="base_link" />
    <child
      link="left_urf_link" />
    <axis
      xyz="0 0 0" />
  </joint>
  <link
    name="rear_urf_link" />
  <joint
    name="rear_urf_joint"
    type="fixed">
    <origin
      xyz="-0.18 0 0.0902"
      rpy="0 0 3.14159265358979" />
    <parent
      link="base_link" />
    <child
      link="rear_urf_link" />
    <axis
      xyz="0 0 0" />
  </joint>
  <link
    name="right_urf_link" />
  <joint
    name="right_urf_joint"
    type="fixed">
    <origin
      xyz="0.0145422866940573 -0.1055 0.0902"
      rpy="0 0 -1.5707963267949" />
    <parent
      link="base_link" />
    <child
      link="right_urf_link" />
    <axis
      xyz="0 0 0" />
  </joint>
  <link
    name="front_left_wheel_link">
    <inertial>
      <origin
        xyz="-9.13569785487844E-06 -0.00111495248212731 4.36496298178307E-07"
        rpy="0 0 0" />
      <mass
        value="0.201564744790293" />
      <inertia
        ixx="0.000328747164153403"
        ixy="-8.85550647204458E-09"
        ixz="-7.63613181374399E-12"
        iyy="0.000623978887109001"
        iyz="-5.84653211658503E-10"
        izz="0.000328729878144945" />
    </inertial>
    <visual>
      <origin
        xyz="0 0 0"
        rpy="0 0 0" />
      <geometry>
        <mesh
          filename="package://lizi_description/meshes/wheel.STL" />
      </geometry>
      <material
        name="">
        <color
          rgba="0.24 0.24 0.24 1" />
      </material>
    </visual>
    <collision>
      <origin
        xyz="0 0 0"
        rpy="${M_PI/2} 0 0" />
      <geometry>
        <cylinder  length="0.025" radius="0.076"/> 
      </geometry>
    </collision>
  </link>
  <joint
    name="front_left_wheel_joint"
    type="continuous">
    <origin
      xyz="0.13 0.1332125 0"
      rpy="0 0 0" />
    <parent
      link="base_link" />
    <child
      link="front_left_wheel_link" />
    <axis
      xyz="0 0.999999999981052 0" />
  </joint>
  <link
    name="rear_left_wheel_link">
    <inertial>
      <origin
        xyz="-9.13569759561361E-06 -0.00111495248195748 4.36496218545773E-07"
        rpy="0 0 0" />
      <mass
        value="0.201564744787106" />
      <inertia
        ixx="0.000328747164152227"
        ixy="-8.85550650155265E-09"
        ixz="-7.63613763619786E-12"
        iyy="0.000623978887108079"
        iyz="-5.84652766925557E-10"
        izz="0.000328729878144284" />
    </inertial>
    <visual>
      <origin
        xyz="0 0 0"
        rpy="0 0 0" />
      <geometry>
        <mesh
          filename="package://lizi_description/meshes/wheel.STL" />
      </geometry>
      <material
        name="">
        <color
          rgba="0.24 0.24 0.24 1" />
      </material>
    </visual>
    <collision>
      <origin
        xyz="0 0 0"
        rpy="${M_PI/2} 0 0" />
      <geometry>
        <cylinder  length="0.025" radius="0.076"/> 
      </geometry>
    </collision>
  </link>
  <joint
    name="rear_left_wheel_joint"
    type="continuous">
    <origin
      xyz="-0.13 0.1332125 0"
      rpy="0 0 0" />
    <parent
      link="base_link" />
    <child
      link="rear_left_wheel_link" />
    <axis
      xyz="0 0.999999999993684 0" />
  </joint>
  <link
    name="front_right_wheel_link">
    <inertial>
      <origin
        xyz="9.13569801772041E-06 0.00111495248556576 4.364813301491E-07"
        rpy="0 0 0" />
      <mass
        value="0.201564744855459" />
      <inertia
        ixx="0.000328747164305643"
        ixy="-8.85550674928916E-09"
        ixz="7.63798343820813E-12"
        iyy="0.000623978887253213"
        iyz="5.84687601938336E-10"
        izz="0.000328729878152203" />
    </inertial>
    <visual>
      <origin
        xyz="0 0 0"
        rpy="0 0 0" />
      <geometry>
        <mesh
          filename="package://lizi_description/meshes/wheel.STL" />
      </geometry>
      <material
        name="">
        <color
          rgba="0.24 0.24 0.24 1" />
      </material>
    </visual>
    <collision>
      <origin
        xyz="0 0 0"
        rpy="${M_PI/2} 0 0" />
      <geometry>
        <cylinder  length="0.025" radius="0.076"/> 
      </geometry>
    </collision>
  </link>
  <joint
    name="front_right_wheel_joint"
    type="continuous">
    <origin
      xyz="0.130001640097326 -0.1332125 0"
      rpy="0 0 0" />
    <parent
      link="base_link" />
    <child
      link="front_right_wheel_link" />
    <axis
      xyz="0 0.999999999981052 0" />
  </joint>
  <link
    name="rear_right_wheel_link">
    <inertial>
      <origin
        xyz="-9.13569793242752E-06 0.00111495248553414 -4.36481284494934E-07"
        rpy="0 0 0" />
      <mass
        value="0.201564744852236" />
      <inertia
        ixx="0.000328747164304387"
        ixy="8.85550684008093E-09"
        ixz="7.63771005834694E-12"
        iyy="0.000623978887252081"
        iyz="-5.84687536019145E-10"
        izz="0.000328729878151301" />
    </inertial>
    <visual>
      <origin
        xyz="0 0 0"
        rpy="0 0 0" />
      <geometry>
        <mesh
          filename="package://lizi_description/meshes/wheel.STL" />
      </geometry>
      <material
        name="">
        <color
          rgba="0.24 0.24 0.24 1" />
      </material>
    </visual>
    <collision>
      <origin
        xyz="0 0 0"
        rpy="${M_PI/2} 0 0" />
      <geometry>
        <cylinder  length="0.025" radius="0.076"/> 
      </geometry>
    </collision>
  </link>
  <joint
    name="rear_right_wheel_joint"
    type="continuous">
    <origin
      xyz="-0.13 -0.1332125 0"
      rpy="0 0 0" />
    <parent
      link="base_link" />
    <child
      link="rear_right_wheel_link" />
    <axis
      xyz="0 0.999999999993684 0" />
  </joint>
  <link
    name="rgb_cam_link" />
  <joint
    name="cam_joint"
    type="fixed">
    <origin
      xyz="0.17275 0.068 0.0202"
      rpy="0 0 0" />
    <parent
      link="base_link" />
    <child
      link="rgb_cam_link" />
    <axis
      xyz="0 0 0" />
  </joint>
  
      <!-- camera depth joints and links -->
    <joint name="camera_depth_joint" type="fixed">
      <origin xyz="0 -0.0122 0" rpy="0 0 0"/>
      <parent link="camera_link"/>
      <child link="camera_depth_frame" />
    </joint>
    <link name="camera_depth_frame"/>

    <joint name="camera_depth_optical_joint" type="fixed">
      <origin xyz="0 0 0" rpy="${-M_PI/2} 0 ${-M_PI/2}" />
      <parent link="camera_depth_frame" />
      <child link="camera_depth_optical_frame" />
    </joint>
    <link name="camera_depth_optical_frame"/>
      
    <!-- camera left IR joints and links -->
    <joint name="camera_left_ir_joint" type="fixed">
      <origin xyz="0 -0.0322 0" rpy="0 0 0" />
      <parent link="camera_link" />
      <child link="camera_left_ir_frame" />
    </joint>
    <link name="camera_left_ir_frame"/>

    <joint name="camera_left_ir_optical_joint" type="fixed">
      <origin xyz="0 0 0" rpy="${-M_PI/2} 0 ${-M_PI/2}" />
      <parent link="camera_left_ir_frame" />
      <child link="camera_left_ir_optical_frame" />
    </joint>
    <link name="camera_left_ir_optical_frame"/>

    <!-- camera right IR joints and links -->
    <joint name="camera_right_ir_joint" type="fixed">
      <origin xyz="0 0.0178 0" rpy="0 0 0" />
      <parent link="camera_link" />
      <child link="camera_right_ir_frame" />
    </joint>
    <link name="camera_right_ir_frame"/>

    <joint name="camera_right_ir_optical_joint" type="fixed">
      <origin xyz="0 0 0" rpy="${-M_PI/2} 0 ${-M_PI/2}" />
      <parent link="camera_right_ir_frame" />
      <child link="camera_right_ir_optical_frame" />
    </joint>
    <link name="camera_right_ir_optical_frame"/>

    <!-- camera fisheye joints and links -->
    <joint name="camera_fisheye_joint" type="fixed">
      <origin xyz="0 0.0322 0" rpy="0 0 0" />
      <parent link="camera_link" />
      <child link="camera_fisheye_frame" />
    </joint>
    <link name="camera_fisheye_frame"/>

    <joint name="camera_fisheye_optical_joint" type="fixed">
      <origin xyz="0 0 0" rpy="${-M_PI/2} 0 ${-M_PI/2}" />
      <parent link="camera_fisheye_frame" />
      <child link="camera_fisheye_optical_frame" />
    </joint>
    <link name="camera_fisheye_optical_frame"/>
    
</robot>